<?xml version="1.0" ?>
<!-- =================================================================================== -->
<!-- |    This document was autogenerated by xacro from src/quadruped_robot_description/urdf/quadruped_robot.urdf.xacro | -->
<!-- |    EDITING THIS FILE BY HAND IS NOT RECOMMENDED                                 | -->
<!-- =================================================================================== -->
<robot name="quadruped">
  <gazebo>
    <plugin filename="ign_ros2_control-system" name="ign_ros2_control::IgnitionROS2ControlPlugin">
      <parameters>/home/rabin/Documents/quadruped_robot/install/quadruped_controller/share/quadruped_controller/config/jtc_controllers.yaml</parameters>
    </plugin>
    <plugin filename="libignition-gazebo-detachable-joint-system.so" name="ignition::gazebo::systems::DetachableJoint">
      <parent_link>rear_left_foot_link</parent_link>
      <child_model>4BarBot</child_model>
      <child_link>rear_left_chain_close_b_link</child_link>
      <attach_topic>close_loop</attach_topic>
    </plugin>
    <!-- <plugin filename="libattach-links.so" name="ignition::gazebo::::systems::AttachLinks">
      <parent>rear_left_chain_close_a_link</parent>
      <child>rear_left_chain_close_b_link</child>
    </plugin> -->
  </gazebo>
  <mujoco>
    <compiler balanceinertia="true" discardvisual="false" meshdir="/home/rabin/Documents/quadruped_robot/install/quadruped_robot_description/share/quadruped_robot_description/meshes"/>
  </mujoco>
  <material name="grey">
    <color rgba="0.5 0.5 0.5 1"/>
  </material>
  <link name="base_link">
    <visual>
      <origin rpy="0 0 3.141592653589793" xyz="0.0 0 0"/>
      <geometry name="base_link">
        <mesh filename="package://quadruped_robot_description/meshes/base_link.dae"/>
      </geometry>
      <material name="grey">
        <color rgba="0.5 0.5 0.5 1.0"/>
      </material>
    </visual>
    <collision>
      <origin rpy="0 0 3.141592653589793" xyz="0.0 0 0"/>
      <geometry name="base_link">
        <mesh filename="package://quadruped_robot_description/meshes/base_link.dae"/>
      </geometry>
    </collision>
    <inertial>
      <origin rpy="0.0 0.0 0.0" xyz="0.01 0 0.06"/>
      <mass value="50.0"/>
      <inertia ixx="0.2526041666666667" ixy="0.0" ixz="0.0" iyy="1.4920833333333334" iyz="0.0" izz="1.6613541666666667"/>
    </inertial>
  </link>
  <link name="imu_link"/>
  <joint name="imu_joint" type="fixed">
    <parent link="base_link"/>
    <child link="imu_link"/>
    <origin rpy=" 0.0 3.141592653589793 0.0" xyz="0.0 0.0 0.1"/>
  </joint>
  <!-- Define the thigh -->
  <link name="rear_left_leg_base_link"/>
  <!-- Define the joints -->
  <joint name="rear_left_base_to_leg_joint" type="fixed">
    <parent link="base_link"/>
    <child link="rear_left_leg_base_link"/>
    <origin rpy="0 0 3.141592653589793" xyz="-0.131 0.06 0.06"/>
  </joint>
  <link name="rear_left_first_link">
    <visual>
      <origin rpy="0 0 0" xyz="0.0 0 0.0"/>
      <geometry>
        <mesh filename="package://quadruped_robot_description/meshes/first_link.dae"/>
      </geometry>
      <material name="grey">
        <color rgba="0.5 0.5 0.5 1.0"/>
      </material>
    </visual>
    <collision name="rear_left_first_link_collision">
      <origin rpy="0 0 0" xyz="0.0 0 0.0"/>
      <geometry>
        <mesh filename="package://quadruped_robot_description/meshes/first_link.dae"/>
      </geometry>
    </collision>
    <inertial>
      <origin rpy="0.0 0.0 0.0" xyz="0.0 0.0 0.0"/>
      <mass value="0.6"/>
      <inertia ixx="0.0004550000000000001" ixy="0" ixz="0" iyy="0.0004550000000000001" iyz="0" izz="0.00075"/>
    </inertial>
  </link>
  <joint name="rear_left_leg_base_to_first_link_joint" type="fixed">
    <parent link="rear_left_leg_base_link"/>
    <child link="rear_left_first_link"/>
    <origin rpy="-1.5707963267948966 0.0 0.0" xyz="0.0 0.0 0.0"/>
  </joint>
  <link name="rear_left_second_link">
    <visual>
      <origin rpy="0 0 0" xyz="0.0 0 0.0"/>
      <geometry>
        <mesh filename="package://quadruped_robot_description/meshes/second_link.dae"/>
      </geometry>
      <material name="grey">
        <color rgba="0.5 0.5 0.5 1.0"/>
      </material>
    </visual>
    <collision name="rear_left_second_link_collision">
      <origin rpy="0 0 0" xyz="0.0 0 0.0"/>
      <geometry>
        <mesh filename="package://quadruped_robot_description/meshes/second_link.dae"/>
      </geometry>
    </collision>
    <inertial>
      <origin rpy="0.0 0.0 0.0" xyz="0.055 0  0"/>
      <mass value="0.6"/>
      <inertia ixx="0.0004550000000000001" ixy="0" ixz="0" iyy="0.0004550000000000001" iyz="0" izz="0.00075"/>
    </inertial>
  </link>
  <joint name="rear_left_first_joint" type="revolute">
    <parent link="rear_left_first_link"/>
    <child link="rear_left_second_link"/>
    <origin rpy="3.141592653589793 0.0 0.0" xyz="0.031 0.0 0.0"/>
    <axis xyz="1 0 0"/>
    <limit effort="100.0" lower="-3.1416" upper="3.1416" velocity="0.1"/>
    <dynamics damping="0.1" friction="0.1"/>
  </joint>
  <link name="rear_left_third_link">
    <visual>
      <origin rpy="0 0 0" xyz="0.0 0 0.0"/>
      <geometry>
        <mesh filename="package://quadruped_robot_description/meshes/third_link.dae"/>
      </geometry>
      <material name="grey">
        <color rgba="0.5 0.5 0.5 1.0"/>
      </material>
    </visual>
    <collision name="rear_left_third_link_collision">
      <origin rpy="0 0 0" xyz="0.0 0 0.0"/>
      <geometry>
        <mesh filename="package://quadruped_robot_description/meshes/third_link.dae"/>
      </geometry>
    </collision>
    <inertial>
      <origin rpy="0.0 0.0 0.0" xyz="0.0 0  0.025"/>
      <mass value="0.6"/>
      <inertia ixx="0.0004550000000000001" ixy="0" ixz="0" iyy="0.0004550000000000001" iyz="0" izz="0.00075"/>
    </inertial>
  </link>
  <joint name="rear_left_second_joint" type="revolute">
    <parent link="rear_left_second_link"/>
    <child link="rear_left_third_link"/>
    <origin rpy="0.0 0.0 3.141592653589793 " xyz="0.064 0.0 0.023"/>
    <axis xyz="0 0 -1"/>
    <limit effort="100.0" lower="-3.14" upper="3.14" velocity="0.1"/>
    <dynamics damping="0.1" friction="0.1"/>
  </joint>
  <link name="rear_left_fourth_link">
    <visual>
      <origin rpy="0 0 0" xyz="0.0 0 0.0"/>
      <geometry>
        <mesh filename="package://quadruped_robot_description/meshes/fourth_link.dae"/>
      </geometry>
      <material name="grey">
        <color rgba="0.5 0.5 0.5 1.0"/>
      </material>
    </visual>
    <collision name="rear_left_fourth_link_collision">
      <origin rpy="0 0 0" xyz="0.0 0 0.0"/>
      <geometry>
        <mesh filename="package://quadruped_robot_description/meshes/fourth_link.dae"/>
      </geometry>
    </collision>
    <inertial>
      <origin rpy="0.0 0.0 0.0" xyz="0.0625 0.0  0.015"/>
      <mass value="0.04"/>
      <inertia ixx="3.1041666666666677e-06" ixy="0.0" ixz="0.0" iyy="0.00010310416666666667" iyz="0.0" izz="0.00010416666666666666"/>
    </inertial>
  </link>
  <joint name="rear_left_third_joint" type="revolute">
    <parent link="rear_left_third_link"/>
    <child link="rear_left_fourth_link"/>
    <origin rpy="0.0 0.0 -3.1415800872191793" xyz="0.0 0.0 0.0555"/>
    <axis xyz="0 0 1"/>
    <limit effort="100.0" lower="0.425" upper="5.8" velocity="0.1"/>
    <!-- <limit effort="100.0" lower="0.425" upper="5.0" velocity="0.1"/> -->
    <dynamics damping="0.1" friction="0.1"/>
  </joint>
  <link name="rear_left_fifth_link">
    <visual>
      <origin rpy="0 0 0" xyz="0.0 0 0.0"/>
      <geometry>
        <mesh filename="package://quadruped_robot_description/meshes/fifth_link.dae"/>
      </geometry>
      <material name="grey">
        <color rgba="0.5 0.5 0.5 1.0"/>
      </material>
    </visual>
    <collision name="rear_left_fifth_link_collision">
      <origin rpy="0 0 0" xyz="0.0 0 0.0"/>
      <geometry>
        <mesh filename="package://quadruped_robot_description/meshes/fifth_link.dae"/>
      </geometry>
    </collision>
    <inertial>
      <origin rpy="0.0 0.0 0.0" xyz="0.105 0  0.0"/>
      <mass value="0.05"/>
      <inertia ixx="7.942708333333334e-06" ixy="0.0" ixz="0.0" iyy="0.0002616927083333333" iyz="0.0" izz="0.00026708333333333337"/>
    </inertial>
  </link>
  <joint name="rear_left_fourth_joint" type="revolute">
    <parent link="rear_left_fourth_link"/>
    <child link="rear_left_fifth_link"/>
    <origin rpy="0.0 0.0 3.141592653589793" xyz="0.125 0.0 0.0255"/>
    <axis xyz="0 0 -1"/>
    <limit effort="  2.0" lower="-0.8" upper="-2.9" velocity="0.1"/>
    <!-- <limit effort="  2.0" lower="-0.3" upper="-2.9" velocity="0.1"/> -->
    <dynamics damping="0.1" friction="0.1"/>
  </joint>
  <link name="rear_left_sixth_link">
    <visual>
      <origin rpy="0 0 0" xyz="0.0 0 0.0"/>
      <geometry>
        <mesh filename="package://quadruped_robot_description/meshes/sixth_link.dae"/>
      </geometry>
      <material name="grey">
        <color rgba="0.5 0.5 0.5 1.0"/>
      </material>
    </visual>
    <collision name="rear_left_sixth_link_collision">
      <origin rpy="0 0 0" xyz="0.0 0 0.0"/>
      <geometry>
        <mesh filename="package://quadruped_robot_description/meshes/sixth_link.dae"/>
      </geometry>
    </collision>
    <inertial>
      <origin rpy="0.0 0.0 0.0" xyz="0.105 0  0.0"/>
      <mass value="0.05"/>
      <inertia ixx="7.942708333333334e-06" ixy="0.0" ixz="0.0" iyy="0.0002616927083333333" iyz="0.0" izz="0.00026708333333333337"/>
    </inertial>
  </link>
  <joint name="rear_left_fifth_joint" type="revolute">
    <parent link="rear_left_third_link"/>
    <child link="rear_left_sixth_link"/>
    <origin rpy="0.0 0.0 0.0" xyz="-0.125 0.0 0.058"/>
    <axis xyz="0 0 -1"/>
    <limit effort="100.0" lower="-3.14" upper="3.14" velocity="0.1"/>
    <!-- <limit effort="100.0" lower="0.28" upper="2.73" velocity="0.1"/> -->
    <dynamics damping="0.1" friction="0.1"/>
  </joint>
  <link name="rear_left_foot_link">
    <visual>
      <origin rpy=" 0 0 0" xyz="0.0 0.0  0.0 "/>
      <geometry>
        <box size="0.0001 0.0001 0.0001 "/>
      </geometry>
      <material name="grey">
        <color rgba="0.5 0.5 0.5 1.0"/>
      </material>
    </visual>
    <collision name="rear_left_foot_link_collision">
      <origin rpy=" 0 0 0" xyz="0.0 0.0  0.0 "/>
      <geometry>
        <box size="0.0001 0.0001 0.0001 "/>
      </geometry>
    </collision>
    <inertial>
      <mass value="2e-06"/>
      <inertia ixx="1.1e-09" ixy="0" ixz="0" iyy="1.1e-09" iyz="0" izz="1.1e-09"/>
    </inertial>
  </link>
  <joint name="rear_left_foot_joint" type="revolute">
    <parent link="rear_left_sixth_link"/>
    <child link="rear_left_foot_link"/>
    <origin rpy="0.0 0.0 0.0" xyz="0.21 0.0 0.0115"/>
    <axis xyz="0 0 1"/>
    <limit effort="100.0" lower="-3.14" upper="3.14" velocity="0.1"/>
    <dynamics damping="0.1" friction="0.1"/>
  </joint>
  <link name="rear_left_chain_close_a_link">
    <visual>
      <origin rpy=" 0 0 0" xyz="0.0 0.0  0.0 "/>
      <geometry>
        <box size="0.0001 0.0001 0.0001 "/>
      </geometry>
      <material name="grey">
        <color rgba="0.5 0.5 0.5 1.0"/>
      </material>
    </visual>
    <collision name="rear_left_chain_close_a_link_collision">
      <origin rpy=" 0 0 0" xyz="0.0 0.0  0.0 "/>
      <geometry>
        <box size="0.0001 0.0001 0.0001 "/>
      </geometry>
    </collision>
    <inertial>
      <mass value="2e-06"/>
      <inertia ixx="1.1e-09" ixy="0" ixz="0" iyy="1.1e-09" iyz="0" izz="1.1e-09"/>
    </inertial>
  </link>
  <joint name="rear_left_chain_close_a_joint" type="fixed">
    <parent link="rear_left_fifth_link"/>
    <child link="rear_left_chain_close_a_link"/>
    <origin rpy="0.0 0.0 0.0" xyz="0.105 0.0 -0.0115"/>
    <axis xyz="0 0 1"/>
  </joint>
  <link name="rear_left_chain_close_b_link">
    <visual>
      <origin rpy=" 0 0 0" xyz="0.0 0.0  0.0 "/>
      <geometry>
        <box size="0.0001 0.0001 0.0001 "/>
      </geometry>
      <material name="grey">
        <color rgba="0.5 0.5 0.5 1.0"/>
      </material>
    </visual>
    <collision name="rear_left_chain_close_b_link_collision">
      <origin rpy=" 0 0 0" xyz="0.0 0.0  0.0 "/>
      <geometry>
        <box size="0.0001 0.0001 0.0001 "/>
      </geometry>
    </collision>
    <inertial>
      <mass value="2e-06"/>
      <inertia ixx="1.1e-09" ixy="0" ixz="0" iyy="1.1e-09" iyz="0" izz="1.1e-09"/>
    </inertial>
  </link>
  <joint name="rear_left_chain_close_b_joint" type="fixed">
    <parent link="rear_left_foot_link"/>
    <child link="rear_left_chain_close_b_link"/>
    <origin rpy="0.0 0.0 0.0" xyz="0.105 0.0 0.0"/>
    <axis xyz="0 0 1"/>
  </joint>
  <!-- Define the thigh -->
  <link name="rear_right_leg_base_link"/>
  <!-- Define the joints -->
  <joint name="rear_right_base_to_leg_joint" type="fixed">
    <parent link="base_link"/>
    <child link="rear_right_leg_base_link"/>
    <origin rpy="0 0 3.141592653589793" xyz="-0.131 -0.06 0.06"/>
  </joint>
  <link name="rear_right_first_link">
    <visual>
      <origin rpy="0 0 0" xyz="0.0 0 0.0"/>
      <geometry>
        <mesh filename="package://quadruped_robot_description/meshes/first_link.dae"/>
      </geometry>
      <material name="grey">
        <color rgba="0.5 0.5 0.5 1.0"/>
      </material>
    </visual>
    <collision name="rear_right_first_link_collision">
      <origin rpy="0 0 0" xyz="0.0 0 0.0"/>
      <geometry>
        <mesh filename="package://quadruped_robot_description/meshes/first_link.dae"/>
      </geometry>
    </collision>
    <inertial>
      <origin rpy="0.0 0.0 0.0" xyz="0.0 0.0 0.0"/>
      <mass value="0.6"/>
      <inertia ixx="0.0004550000000000001" ixy="0" ixz="0" iyy="0.0004550000000000001" iyz="0" izz="0.00075"/>
    </inertial>
  </link>
  <joint name="rear_right_leg_base_to_first_link_joint" type="fixed">
    <parent link="rear_right_leg_base_link"/>
    <child link="rear_right_first_link"/>
    <origin rpy="-1.5707963267948966 0.0 0.0" xyz="0.0 0.0 0.0"/>
  </joint>
  <link name="rear_right_second_link">
    <visual>
      <origin rpy="0 0 0" xyz="0.0 0 0.0"/>
      <geometry>
        <mesh filename="package://quadruped_robot_description/meshes/second_link.dae"/>
      </geometry>
      <material name="grey">
        <color rgba="0.5 0.5 0.5 1.0"/>
      </material>
    </visual>
    <collision name="rear_right_second_link_collision">
      <origin rpy="0 0 0" xyz="0.0 0 0.0"/>
      <geometry>
        <mesh filename="package://quadruped_robot_description/meshes/second_link.dae"/>
      </geometry>
    </collision>
    <inertial>
      <origin rpy="0.0 0.0 0.0" xyz="0.055 0  0"/>
      <mass value="0.6"/>
      <inertia ixx="0.0004550000000000001" ixy="0" ixz="0" iyy="0.0004550000000000001" iyz="0" izz="0.00075"/>
    </inertial>
  </link>
  <joint name="rear_right_first_joint" type="revolute">
    <parent link="rear_right_first_link"/>
    <child link="rear_right_second_link"/>
    <origin rpy="0.0 0.0 0.0" xyz="0.031 0.0 0.0"/>
    <axis xyz="1 0 0"/>
    <limit effort="100.0" lower="-3.1416" upper="3.1416" velocity="0.1"/>
    <dynamics damping="0.1" friction="0.1"/>
  </joint>
  <link name="rear_right_third_link">
    <visual>
      <origin rpy="0 0 0" xyz="0.0 0 0.0"/>
      <geometry>
        <mesh filename="package://quadruped_robot_description/meshes/third_link.dae"/>
      </geometry>
      <material name="grey">
        <color rgba="0.5 0.5 0.5 1.0"/>
      </material>
    </visual>
    <collision name="rear_right_third_link_collision">
      <origin rpy="0 0 0" xyz="0.0 0 0.0"/>
      <geometry>
        <mesh filename="package://quadruped_robot_description/meshes/third_link.dae"/>
      </geometry>
    </collision>
    <inertial>
      <origin rpy="0.0 0.0 0.0" xyz="0.0 0  0.025"/>
      <mass value="0.6"/>
      <inertia ixx="0.0004550000000000001" ixy="0" ixz="0" iyy="0.0004550000000000001" iyz="0" izz="0.00075"/>
    </inertial>
  </link>
  <joint name="rear_right_second_joint" type="revolute">
    <parent link="rear_right_second_link"/>
    <child link="rear_right_third_link"/>
    <origin rpy="0.0 0.0 3.141592653589793 " xyz="0.064 0.0 0.023"/>
    <axis xyz="0 0 1"/>
    <limit effort="100.0" lower="-3.14" upper="3.14" velocity="0.1"/>
    <dynamics damping="0.1" friction="0.1"/>
  </joint>
  <link name="rear_right_fourth_link">
    <visual>
      <origin rpy="0 0 0" xyz="0.0 0 0.0"/>
      <geometry>
        <mesh filename="package://quadruped_robot_description/meshes/fourth_link.dae"/>
      </geometry>
      <material name="grey">
        <color rgba="0.5 0.5 0.5 1.0"/>
      </material>
    </visual>
    <collision name="rear_right_fourth_link_collision">
      <origin rpy="0 0 0" xyz="0.0 0 0.0"/>
      <geometry>
        <mesh filename="package://quadruped_robot_description/meshes/fourth_link.dae"/>
      </geometry>
    </collision>
    <inertial>
      <origin rpy="0.0 0.0 0.0" xyz="0.0625 0.0  0.015"/>
      <mass value="0.04"/>
      <inertia ixx="3.1041666666666677e-06" ixy="0.0" ixz="0.0" iyy="0.00010310416666666667" iyz="0.0" izz="0.00010416666666666666"/>
    </inertial>
  </link>
  <joint name="rear_right_third_joint" type="revolute">
    <parent link="rear_right_third_link"/>
    <child link="rear_right_fourth_link"/>
    <origin rpy="0.0 0.0 3.1415800872191793" xyz="0.0 0.0 0.0555"/>
    <axis xyz="0 0 -1"/>
    <limit effort="100.0" lower="0.425" upper="5.8" velocity="0.1"/>
    <dynamics damping="0.1" friction="0.1"/>
  </joint>
  <link name="rear_right_fifth_link">
    <visual>
      <origin rpy="0 0 0" xyz="0.0 0 0.0"/>
      <geometry>
        <mesh filename="package://quadruped_robot_description/meshes/fifth_link.dae"/>
      </geometry>
      <material name="grey">
        <color rgba="0.5 0.5 0.5 1.0"/>
      </material>
    </visual>
    <collision name="rear_right_fifth_link_collision">
      <origin rpy="0 0 0" xyz="0.0 0 0.0"/>
      <geometry>
        <mesh filename="package://quadruped_robot_description/meshes/fifth_link.dae"/>
      </geometry>
    </collision>
    <inertial>
      <origin rpy="0.0 0.0 0.0" xyz="0.105 0  0.0"/>
      <mass value="0.05"/>
      <inertia ixx="7.942708333333334e-06" ixy="0.0" ixz="0.0" iyy="0.0002616927083333333" iyz="0.0" izz="0.00026708333333333337"/>
    </inertial>
  </link>
  <joint name="rear_right_fourth_joint" type="revolute">
    <parent link="rear_right_fourth_link"/>
    <child link="rear_right_fifth_link"/>
    <origin rpy="0.0 0.0 3.141592653589793" xyz="0.125 0.0 0.0255"/>
    <axis xyz="0 0 -1"/>
    <limit effort="  2.0" lower="-0.8" upper="-2.9" velocity="0.1"/>
    <dynamics damping="0.1" friction="0.1"/>
  </joint>
  <link name="rear_right_sixth_link">
    <visual>
      <origin rpy="0 0 0" xyz="0.0 0 0.0"/>
      <geometry>
        <mesh filename="package://quadruped_robot_description/meshes/sixth_link.dae"/>
      </geometry>
      <material name="grey">
        <color rgba="0.5 0.5 0.5 1.0"/>
      </material>
    </visual>
    <collision name="rear_right_sixth_link_collision">
      <origin rpy="0 0 0" xyz="0.0 0 0.0"/>
      <geometry>
        <mesh filename="package://quadruped_robot_description/meshes/sixth_link.dae"/>
      </geometry>
    </collision>
    <inertial>
      <origin rpy="0.0 0.0 0.0" xyz="0.105 0  0.0"/>
      <mass value="0.05"/>
      <inertia ixx="7.942708333333334e-06" ixy="0.0" ixz="0.0" iyy="0.0002616927083333333" iyz="0.0" izz="0.00026708333333333337"/>
    </inertial>
  </link>
  <joint name="rear_right_fifth_joint" type="revolute">
    <parent link="rear_right_third_link"/>
    <child link="rear_right_sixth_link"/>
    <origin rpy="0.0 0.0 0.0" xyz="-0.125 0.0 0.058"/>
    <axis xyz="0 0 -1"/>
    <limit effort="100.0" lower="-3.14" upper="3.14" velocity="0.1"/>
    <dynamics damping="0.1" friction="0.1"/>
  </joint>
  <link name="rear_right_foot_link">
    <visual>
      <origin rpy=" 0 0 0" xyz="0.0 0.0  0.0 "/>
      <geometry>
        <box size="0.0001 0.0001 0.0001 "/>
      </geometry>
      <material name="grey">
        <color rgba="0.5 0.5 0.5 1.0"/>
      </material>
    </visual>
    <collision name="rear_right_foot_link_collision">
      <origin rpy=" 0 0 0" xyz="0.0 0.0  0.0 "/>
      <geometry>
        <box size="0.0001 0.0001 0.0001 "/>
      </geometry>
    </collision>
    <inertial>
      <mass value="2e-06"/>
      <inertia ixx="1.1e-09" ixy="0" ixz="0" iyy="1.1e-09" iyz="0" izz="1.1e-09"/>
    </inertial>
  </link>
  <joint name="rear_right_foot_joint" type="revolute">
    <parent link="rear_right_sixth_link"/>
    <child link="rear_right_foot_link"/>
    <origin rpy="0.0 0.0 0.0" xyz="0.21 0.0 0.0115"/>
    <axis xyz="0 0 1"/>
    <limit effort="100.0" lower="-3.14" upper="3.14" velocity="0.1"/>
    <dynamics damping="0.1" friction="0.1"/>
  </joint>
  <link name="rear_right_chain_close_a_link">
    <visual>
      <origin rpy=" 0 0 0" xyz="0.0 0.0  0.0 "/>
      <geometry>
        <box size="0.0001 0.0001 0.0001 "/>
      </geometry>
      <material name="grey">
        <color rgba="0.5 0.5 0.5 1.0"/>
      </material>
    </visual>
    <collision name="rear_right_chain_close_a_link_collision">
      <origin rpy=" 0 0 0" xyz="0.0 0.0  0.0 "/>
      <geometry>
        <box size="0.0001 0.0001 0.0001 "/>
      </geometry>
    </collision>
    <inertial>
      <mass value="2e-06"/>
      <inertia ixx="1.1e-09" ixy="0" ixz="0" iyy="1.1e-09" iyz="0" izz="1.1e-09"/>
    </inertial>
  </link>
  <joint name="rear_right_chain_close_a_joint" type="fixed">
    <parent link="rear_right_fifth_link"/>
    <child link="rear_right_chain_close_a_link"/>
    <origin rpy="0.0 0.0 0.0" xyz="0.105 0.0 -0.0115"/>
    <axis xyz="0 0 1"/>
  </joint>
  <link name="rear_right_chain_close_b_link">
    <visual>
      <origin rpy=" 0 0 0" xyz="0.0 0.0  0.0 "/>
      <geometry>
        <box size="0.0001 0.0001 0.0001 "/>
      </geometry>
      <material name="grey">
        <color rgba="0.5 0.5 0.5 1.0"/>
      </material>
    </visual>
    <collision name="rear_right_chain_close_b_link_collision">
      <origin rpy=" 0 0 0" xyz="0.0 0.0  0.0 "/>
      <geometry>
        <box size="0.0001 0.0001 0.0001 "/>
      </geometry>
    </collision>
    <inertial>
      <mass value="2e-06"/>
      <inertia ixx="1.1e-09" ixy="0" ixz="0" iyy="1.1e-09" iyz="0" izz="1.1e-09"/>
    </inertial>
  </link>
  <joint name="rear_right_chain_close_b_joint" type="fixed">
    <parent link="rear_right_foot_link"/>
    <child link="rear_right_chain_close_b_link"/>
    <origin rpy="0.0 0.0 0.0" xyz="0.105 0.0 0.0"/>
    <axis xyz="0 0 1"/>
  </joint>
  <!-- Define the thigh -->
  <link name="front_right_leg_base_link"/>
  <!-- Define the joints -->
  <joint name="front_right_base_to_leg_joint" type="fixed">
    <parent link="base_link"/>
    <child link="front_right_leg_base_link"/>
    <origin rpy="0 0 0" xyz="0.131 -0.06 0.06"/>
  </joint>
  <link name="front_right_first_link">
    <visual>
      <origin rpy="0 0 0" xyz="0.0 0 0.0"/>
      <geometry>
        <mesh filename="package://quadruped_robot_description/meshes/first_link.dae"/>
      </geometry>
      <material name="grey">
        <color rgba="0.5 0.5 0.5 1.0"/>
      </material>
    </visual>
    <collision name="front_right_first_link_collision">
      <origin rpy="0 0 0" xyz="0.0 0 0.0"/>
      <geometry>
        <mesh filename="package://quadruped_robot_description/meshes/first_link.dae"/>
      </geometry>
    </collision>
    <inertial>
      <origin rpy="0.0 0.0 0.0" xyz="0.0 0.0 0.0"/>
      <mass value="0.6"/>
      <inertia ixx="0.0004550000000000001" ixy="0" ixz="0" iyy="0.0004550000000000001" iyz="0" izz="0.00075"/>
    </inertial>
  </link>
  <joint name="front_right_leg_base_to_first_link_joint" type="fixed">
    <parent link="front_right_leg_base_link"/>
    <child link="front_right_first_link"/>
    <origin rpy="-1.5707963267948966 0.0 0.0" xyz="0.0 0.0 0.0"/>
  </joint>
  <link name="front_right_second_link">
    <visual>
      <origin rpy="0 0 0" xyz="0.0 0 0.0"/>
      <geometry>
        <mesh filename="package://quadruped_robot_description/meshes/second_link.dae"/>
      </geometry>
      <material name="grey">
        <color rgba="0.5 0.5 0.5 1.0"/>
      </material>
    </visual>
    <collision name="front_right_second_link_collision">
      <origin rpy="0 0 0" xyz="0.0 0 0.0"/>
      <geometry>
        <mesh filename="package://quadruped_robot_description/meshes/second_link.dae"/>
      </geometry>
    </collision>
    <inertial>
      <origin rpy="0.0 0.0 0.0" xyz="0.055 0  0"/>
      <mass value="0.6"/>
      <inertia ixx="0.0004550000000000001" ixy="0" ixz="0" iyy="0.0004550000000000001" iyz="0" izz="0.00075"/>
    </inertial>
  </link>
  <joint name="front_right_first_joint" type="revolute">
    <parent link="front_right_first_link"/>
    <child link="front_right_second_link"/>
    <origin rpy="3.141592653589793 0.0 0.0" xyz="0.031 0.0 0.0"/>
    <axis xyz="1 0 0"/>
    <limit effort="100.0" lower="-3.1416" upper="3.1416" velocity="0.1"/>
    <dynamics damping="0.1" friction="0.1"/>
  </joint>
  <link name="front_right_third_link">
    <visual>
      <origin rpy="0 0 0" xyz="0.0 0 0.0"/>
      <geometry>
        <mesh filename="package://quadruped_robot_description/meshes/third_link.dae"/>
      </geometry>
      <material name="grey">
        <color rgba="0.5 0.5 0.5 1.0"/>
      </material>
    </visual>
    <collision name="front_right_third_link_collision">
      <origin rpy="0 0 0" xyz="0.0 0 0.0"/>
      <geometry>
        <mesh filename="package://quadruped_robot_description/meshes/third_link.dae"/>
      </geometry>
    </collision>
    <inertial>
      <origin rpy="0.0 0.0 0.0" xyz="0.0 0  0.025"/>
      <mass value="0.6"/>
      <inertia ixx="0.0004550000000000001" ixy="0" ixz="0" iyy="0.0004550000000000001" iyz="0" izz="0.00075"/>
    </inertial>
  </link>
  <joint name="front_right_second_joint" type="revolute">
    <parent link="front_right_second_link"/>
    <child link="front_right_third_link"/>
    <origin rpy="0.0 0.0 3.141592653589793 " xyz="0.064 0.0 0.023"/>
    <axis xyz="0 0 -1"/>
    <limit effort="100.0" lower="-3.14" upper="3.14" velocity="0.1"/>
    <dynamics damping="0.1" friction="0.1"/>
  </joint>
  <link name="front_right_fourth_link">
    <visual>
      <origin rpy="0 0 0" xyz="0.0 0 0.0"/>
      <geometry>
        <mesh filename="package://quadruped_robot_description/meshes/fourth_link.dae"/>
      </geometry>
      <material name="grey">
        <color rgba="0.5 0.5 0.5 1.0"/>
      </material>
    </visual>
    <collision name="front_right_fourth_link_collision">
      <origin rpy="0 0 0" xyz="0.0 0 0.0"/>
      <geometry>
        <mesh filename="package://quadruped_robot_description/meshes/fourth_link.dae"/>
      </geometry>
    </collision>
    <inertial>
      <origin rpy="0.0 0.0 0.0" xyz="0.0625 0.0  0.015"/>
      <mass value="0.04"/>
      <inertia ixx="3.1041666666666677e-06" ixy="0.0" ixz="0.0" iyy="0.00010310416666666667" iyz="0.0" izz="0.00010416666666666666"/>
    </inertial>
  </link>
  <joint name="front_right_third_joint" type="revolute">
    <parent link="front_right_third_link"/>
    <child link="front_right_fourth_link"/>
    <origin rpy="0.0 0.0 -3.1415800872191793" xyz="0.0 0.0 0.0555"/>
    <axis xyz="0 0 1"/>
    <limit effort="100.0" lower="0.425" upper="5.8" velocity="0.1"/>
    <dynamics damping="0.1" friction="0.1"/>
  </joint>
  <link name="front_right_fifth_link">
    <visual>
      <origin rpy="0 0 0" xyz="0.0 0 0.0"/>
      <geometry>
        <mesh filename="package://quadruped_robot_description/meshes/fifth_link.dae"/>
      </geometry>
      <material name="grey">
        <color rgba="0.5 0.5 0.5 1.0"/>
      </material>
    </visual>
    <collision name="front_right_fifth_link_collision">
      <origin rpy="0 0 0" xyz="0.0 0 0.0"/>
      <geometry>
        <mesh filename="package://quadruped_robot_description/meshes/fifth_link.dae"/>
      </geometry>
    </collision>
    <inertial>
      <origin rpy="0.0 0.0 0.0" xyz="0.105 0  0.0"/>
      <mass value="0.05"/>
      <inertia ixx="7.942708333333334e-06" ixy="0.0" ixz="0.0" iyy="0.0002616927083333333" iyz="0.0" izz="0.00026708333333333337"/>
    </inertial>
  </link>
  <joint name="front_right_fourth_joint" type="revolute">
    <parent link="front_right_fourth_link"/>
    <child link="front_right_fifth_link"/>
    <origin rpy="0.0 0.0 3.141592653589793" xyz="0.125 0.0 0.0255"/>
    <axis xyz="0 0 -1"/>
    <limit effort="  2.0" lower="-0.8" upper="-2.9" velocity="0.1"/>
    <dynamics damping="0.1" friction="0.1"/>
  </joint>
  <link name="front_right_sixth_link">
    <visual>
      <origin rpy="0 0 0" xyz="0.0 0 0.0"/>
      <geometry>
        <mesh filename="package://quadruped_robot_description/meshes/sixth_link.dae"/>
      </geometry>
      <material name="grey">
        <color rgba="0.5 0.5 0.5 1.0"/>
      </material>
    </visual>
    <collision name="front_right_sixth_link_collision">
      <origin rpy="0 0 0" xyz="0.0 0 0.0"/>
      <geometry>
        <mesh filename="package://quadruped_robot_description/meshes/sixth_link.dae"/>
      </geometry>
    </collision>
    <inertial>
      <origin rpy="0.0 0.0 0.0" xyz="0.105 0  0.0"/>
      <mass value="0.05"/>
      <inertia ixx="7.942708333333334e-06" ixy="0.0" ixz="0.0" iyy="0.0002616927083333333" iyz="0.0" izz="0.00026708333333333337"/>
    </inertial>
  </link>
  <joint name="front_right_fifth_joint" type="revolute">
    <parent link="front_right_third_link"/>
    <child link="front_right_sixth_link"/>
    <origin rpy="0.0 0.0 0.0" xyz="-0.125 0.0 0.058"/>
    <axis xyz="0 0 -1"/>
    <limit effort="100.0" lower="-3.14" upper="3.14" velocity="0.1"/>
    <dynamics damping="0.1" friction="0.1"/>
  </joint>
  <link name="front_right_foot_link">
    <visual>
      <origin rpy=" 0 0 0" xyz="0.0 0.0  0.0 "/>
      <geometry>
        <box size="0.0001 0.0001 0.0001 "/>
      </geometry>
      <material name="grey">
        <color rgba="0.5 0.5 0.5 1.0"/>
      </material>
    </visual>
    <collision name="front_right_foot_link_collision">
      <origin rpy=" 0 0 0" xyz="0.0 0.0  0.0 "/>
      <geometry>
        <box size="0.0001 0.0001 0.0001 "/>
      </geometry>
    </collision>
    <inertial>
      <mass value="2e-06"/>
      <inertia ixx="1.1e-09" ixy="0" ixz="0" iyy="1.1e-09" iyz="0" izz="1.1e-09"/>
    </inertial>
  </link>
  <joint name="front_right_foot_joint" type="revolute">
    <parent link="front_right_sixth_link"/>
    <child link="front_right_foot_link"/>
    <origin rpy="0.0 0.0 0.0" xyz="0.21 0.0 0.0115"/>
    <axis xyz="0 0 1"/>
    <limit effort="100.0" lower="-3.14" upper="3.14" velocity="0.1"/>
    <dynamics damping="0.1" friction="0.1"/>
  </joint>
  <link name="front_right_chain_close_a_link">
    <visual>
      <origin rpy=" 0 0 0" xyz="0.0 0.0  0.0 "/>
      <geometry>
        <box size="0.0001 0.0001 0.0001 "/>
      </geometry>
      <material name="grey">
        <color rgba="0.5 0.5 0.5 1.0"/>
      </material>
    </visual>
    <collision name="front_right_chain_close_a_link_collision">
      <origin rpy=" 0 0 0" xyz="0.0 0.0  0.0 "/>
      <geometry>
        <box size="0.0001 0.0001 0.0001 "/>
      </geometry>
    </collision>
    <inertial>
      <mass value="2e-06"/>
      <inertia ixx="1.1e-09" ixy="0" ixz="0" iyy="1.1e-09" iyz="0" izz="1.1e-09"/>
    </inertial>
  </link>
  <joint name="front_right_chain_close_a_joint" type="fixed">
    <parent link="front_right_fifth_link"/>
    <child link="front_right_chain_close_a_link"/>
    <origin rpy="0.0 0.0 0.0" xyz="0.105 0.0 -0.0115"/>
    <axis xyz="0 0 1"/>
  </joint>
  <link name="front_right_chain_close_b_link">
    <visual>
      <origin rpy=" 0 0 0" xyz="0.0 0.0  0.0 "/>
      <geometry>
        <box size="0.0001 0.0001 0.0001 "/>
      </geometry>
      <material name="grey">
        <color rgba="0.5 0.5 0.5 1.0"/>
      </material>
    </visual>
    <collision name="front_right_chain_close_b_link_collision">
      <origin rpy=" 0 0 0" xyz="0.0 0.0  0.0 "/>
      <geometry>
        <box size="0.0001 0.0001 0.0001 "/>
      </geometry>
    </collision>
    <inertial>
      <mass value="2e-06"/>
      <inertia ixx="1.1e-09" ixy="0" ixz="0" iyy="1.1e-09" iyz="0" izz="1.1e-09"/>
    </inertial>
  </link>
  <joint name="front_right_chain_close_b_joint" type="fixed">
    <parent link="front_right_foot_link"/>
    <child link="front_right_chain_close_b_link"/>
    <origin rpy="0.0 0.0 0.0" xyz="0.105 0.0 0.0"/>
    <axis xyz="0 0 1"/>
  </joint>
  <!-- Define the thigh -->
  <link name="front_left_leg_base_link"/>
  <!-- Define the joints -->
  <joint name="front_left_base_to_leg_joint" type="fixed">
    <parent link="base_link"/>
    <child link="front_left_leg_base_link"/>
    <origin rpy="0 0 0" xyz="0.131 0.06 0.06"/>
  </joint>
  <link name="front_left_first_link">
    <visual>
      <origin rpy="0 0 0" xyz="0.0 0 0.0"/>
      <geometry>
        <mesh filename="package://quadruped_robot_description/meshes/first_link.dae"/>
      </geometry>
      <material name="grey">
        <color rgba="0.5 0.5 0.5 1.0"/>
      </material>
    </visual>
    <collision name="front_left_first_link_collision">
      <origin rpy="0 0 0" xyz="0.0 0 0.0"/>
      <geometry>
        <mesh filename="package://quadruped_robot_description/meshes/first_link.dae"/>
      </geometry>
    </collision>
    <inertial>
      <origin rpy="0.0 0.0 0.0" xyz="0.0 0.0 0.0"/>
      <mass value="0.6"/>
      <inertia ixx="0.0004550000000000001" ixy="0" ixz="0" iyy="0.0004550000000000001" iyz="0" izz="0.00075"/>
    </inertial>
  </link>
  <joint name="front_left_leg_base_to_first_link_joint" type="fixed">
    <parent link="front_left_leg_base_link"/>
    <child link="front_left_first_link"/>
    <origin rpy="-1.5707963267948966 0.0 0.0" xyz="0.0 0.0 0.0"/>
  </joint>
  <link name="front_left_second_link">
    <visual>
      <origin rpy="0 0 0" xyz="0.0 0 0.0"/>
      <geometry>
        <mesh filename="package://quadruped_robot_description/meshes/second_link.dae"/>
      </geometry>
      <material name="grey">
        <color rgba="0.5 0.5 0.5 1.0"/>
      </material>
    </visual>
    <collision name="front_left_second_link_collision">
      <origin rpy="0 0 0" xyz="0.0 0 0.0"/>
      <geometry>
        <mesh filename="package://quadruped_robot_description/meshes/second_link.dae"/>
      </geometry>
    </collision>
    <inertial>
      <origin rpy="0.0 0.0 0.0" xyz="0.055 0  0"/>
      <mass value="0.6"/>
      <inertia ixx="0.0004550000000000001" ixy="0" ixz="0" iyy="0.0004550000000000001" iyz="0" izz="0.00075"/>
    </inertial>
  </link>
  <joint name="front_left_first_joint" type="revolute">
    <parent link="front_left_first_link"/>
    <child link="front_left_second_link"/>
    <origin rpy="0.0 0.0 0.0" xyz="0.031 0.0 0.0"/>
    <axis xyz="1 0 0"/>
    <limit effort="100.0" lower="-3.1416" upper="3.1416" velocity="0.1"/>
    <dynamics damping="0.1" friction="0.1"/>
  </joint>
  <link name="front_left_third_link">
    <visual>
      <origin rpy="0 0 0" xyz="0.0 0 0.0"/>
      <geometry>
        <mesh filename="package://quadruped_robot_description/meshes/third_link.dae"/>
      </geometry>
      <material name="grey">
        <color rgba="0.5 0.5 0.5 1.0"/>
      </material>
    </visual>
    <collision name="front_left_third_link_collision">
      <origin rpy="0 0 0" xyz="0.0 0 0.0"/>
      <geometry>
        <mesh filename="package://quadruped_robot_description/meshes/third_link.dae"/>
      </geometry>
    </collision>
    <inertial>
      <origin rpy="0.0 0.0 0.0" xyz="0.0 0  0.025"/>
      <mass value="0.6"/>
      <inertia ixx="0.0004550000000000001" ixy="0" ixz="0" iyy="0.0004550000000000001" iyz="0" izz="0.00075"/>
    </inertial>
  </link>
  <joint name="front_left_second_joint" type="revolute">
    <parent link="front_left_second_link"/>
    <child link="front_left_third_link"/>
    <origin rpy="0.0 0.0 3.141592653589793 " xyz="0.064 0.0 0.023"/>
    <axis xyz="0 0 1"/>
    <limit effort="100.0" lower="-3.14" upper="3.14" velocity="0.1"/>
    <dynamics damping="0.1" friction="0.1"/>
  </joint>
  <link name="front_left_fourth_link">
    <visual>
      <origin rpy="0 0 0" xyz="0.0 0 0.0"/>
      <geometry>
        <mesh filename="package://quadruped_robot_description/meshes/fourth_link.dae"/>
      </geometry>
      <material name="grey">
        <color rgba="0.5 0.5 0.5 1.0"/>
      </material>
    </visual>
    <collision name="front_left_fourth_link_collision">
      <origin rpy="0 0 0" xyz="0.0 0 0.0"/>
      <geometry>
        <mesh filename="package://quadruped_robot_description/meshes/fourth_link.dae"/>
      </geometry>
    </collision>
    <inertial>
      <origin rpy="0.0 0.0 0.0" xyz="0.0625 0.0  0.015"/>
      <mass value="0.04"/>
      <inertia ixx="3.1041666666666677e-06" ixy="0.0" ixz="0.0" iyy="0.00010310416666666667" iyz="0.0" izz="0.00010416666666666666"/>
    </inertial>
  </link>
  <joint name="front_left_third_joint" type="revolute">
    <parent link="front_left_third_link"/>
    <child link="front_left_fourth_link"/>
    <origin rpy="0.0 0.0 3.1415800872191793" xyz="0.0 0.0 0.0555"/>
    <axis xyz="0 0 -1"/>
    <limit effort="100.0" lower="0.425" upper="5.8" velocity="0.1"/>
    <dynamics damping="0.1" friction="0.1"/>
  </joint>
  <link name="front_left_fifth_link">
    <visual>
      <origin rpy="0 0 0" xyz="0.0 0 0.0"/>
      <geometry>
        <mesh filename="package://quadruped_robot_description/meshes/fifth_link.dae"/>
      </geometry>
      <material name="grey">
        <color rgba="0.5 0.5 0.5 1.0"/>
      </material>
    </visual>
    <collision name="front_left_fifth_link_collision">
      <origin rpy="0 0 0" xyz="0.0 0 0.0"/>
      <geometry>
        <mesh filename="package://quadruped_robot_description/meshes/fifth_link.dae"/>
      </geometry>
    </collision>
    <inertial>
      <origin rpy="0.0 0.0 0.0" xyz="0.105 0  0.0"/>
      <mass value="0.05"/>
      <inertia ixx="7.942708333333334e-06" ixy="0.0" ixz="0.0" iyy="0.0002616927083333333" iyz="0.0" izz="0.00026708333333333337"/>
    </inertial>
  </link>
  <joint name="front_left_fourth_joint" type="revolute">
    <parent link="front_left_fourth_link"/>
    <child link="front_left_fifth_link"/>
    <origin rpy="0.0 0.0 3.141592653589793" xyz="0.125 0.0 0.0255"/>
    <axis xyz="0 0 -1"/>
    <limit effort="  2.0" lower="-0.8" upper="-2.9" velocity="0.1"/>
    <dynamics damping="0.1" friction="0.1"/>
  </joint>
  <link name="front_left_sixth_link">
    <visual>
      <origin rpy="0 0 0" xyz="0.0 0 0.0"/>
      <geometry>
        <mesh filename="package://quadruped_robot_description/meshes/sixth_link.dae"/>
      </geometry>
      <material name="grey">
        <color rgba="0.5 0.5 0.5 1.0"/>
      </material>
    </visual>
    <collision name="front_left_sixth_link_collision">
      <origin rpy="0 0 0" xyz="0.0 0 0.0"/>
      <geometry>
        <mesh filename="package://quadruped_robot_description/meshes/sixth_link.dae"/>
      </geometry>
    </collision>
    <inertial>
      <origin rpy="0.0 0.0 0.0" xyz="0.105 0  0.0"/>
      <mass value="0.05"/>
      <inertia ixx="7.942708333333334e-06" ixy="0.0" ixz="0.0" iyy="0.0002616927083333333" iyz="0.0" izz="0.00026708333333333337"/>
    </inertial>
  </link>
  <joint name="front_left_fifth_joint" type="revolute">
    <parent link="front_left_third_link"/>
    <child link="front_left_sixth_link"/>
    <origin rpy="0.0 0.0 0.0" xyz="-0.125 0.0 0.058"/>
    <axis xyz="0 0 -1"/>
    <limit effort="100.0" lower="-3.14" upper="3.14" velocity="0.1"/>
    <dynamics damping="0.1" friction="0.1"/>
  </joint>
  <link name="front_left_foot_link">
    <visual>
      <origin rpy=" 0 0 0" xyz="0.0 0.0  0.0 "/>
      <geometry>
        <box size="0.0001 0.0001 0.0001 "/>
      </geometry>
      <material name="grey">
        <color rgba="0.5 0.5 0.5 1.0"/>
      </material>
    </visual>
    <collision name="front_left_foot_link_collision">
      <origin rpy=" 0 0 0" xyz="0.0 0.0  0.0 "/>
      <geometry>
        <box size="0.0001 0.0001 0.0001 "/>
      </geometry>
    </collision>
    <inertial>
      <mass value="2e-06"/>
      <inertia ixx="1.1e-09" ixy="0" ixz="0" iyy="1.1e-09" iyz="0" izz="1.1e-09"/>
    </inertial>
  </link>
  <joint name="front_left_foot_joint" type="revolute">
    <parent link="front_left_sixth_link"/>
    <child link="front_left_foot_link"/>
    <origin rpy="0.0 0.0 0.0" xyz="0.21 0.0 0.0115"/>
    <axis xyz="0 0 1"/>
    <limit effort="100.0" lower="-3.14" upper="3.14" velocity="0.1"/>
    <dynamics damping="0.1" friction="0.1"/>
  </joint>
  <link name="front_left_chain_close_a_link">
    <visual>
      <origin rpy=" 0 0 0" xyz="0.0 0.0  0.0 "/>
      <geometry>
        <box size="0.0001 0.0001 0.0001 "/>
      </geometry>
      <material name="grey">
        <color rgba="0.5 0.5 0.5 1.0"/>
      </material>
    </visual>
    <collision name="front_left_chain_close_a_link_collision">
      <origin rpy=" 0 0 0" xyz="0.0 0.0  0.0 "/>
      <geometry>
        <box size="0.0001 0.0001 0.0001 "/>
      </geometry>
    </collision>
    <inertial>
      <mass value="2e-06"/>
      <inertia ixx="1.1e-09" ixy="0" ixz="0" iyy="1.1e-09" iyz="0" izz="1.1e-09"/>
    </inertial>
  </link>
  <joint name="front_left_chain_close_a_joint" type="fixed">
    <parent link="front_left_fifth_link"/>
    <child link="front_left_chain_close_a_link"/>
    <origin rpy="0.0 0.0 0.0" xyz="0.105 0.0 -0.0115"/>
    <axis xyz="0 0 1"/>
  </joint>
  <link name="front_left_chain_close_b_link">
    <visual>
      <origin rpy=" 0 0 0" xyz="0.0 0.0  0.0 "/>
      <geometry>
        <box size="0.0001 0.0001 0.0001 "/>
      </geometry>
      <material name="grey">
        <color rgba="0.5 0.5 0.5 1.0"/>
      </material>
    </visual>
    <collision name="front_left_chain_close_b_link_collision">
      <origin rpy=" 0 0 0" xyz="0.0 0.0  0.0 "/>
      <geometry>
        <box size="0.0001 0.0001 0.0001 "/>
      </geometry>
    </collision>
    <inertial>
      <mass value="2e-06"/>
      <inertia ixx="1.1e-09" ixy="0" ixz="0" iyy="1.1e-09" iyz="0" izz="1.1e-09"/>
    </inertial>
  </link>
  <joint name="front_left_chain_close_b_joint" type="fixed">
    <parent link="front_left_foot_link"/>
    <child link="front_left_chain_close_b_link"/>
    <origin rpy="0.0 0.0 0.0" xyz="0.105 0.0 0.0"/>
    <axis xyz="0 0 1"/>
  </joint>
  <ros2_control name="MD80HardwareInterface" type="system">
    <hardware>
      <plugin>mujoco_ros2_control/MujocoSystem</plugin>
    </hardware>
     <joint name="front_left_first_joint">
      <command_interface name="effort">
          <param name="front_left_first_joint_kp">0.00001</param>
          <param name="kd">0.0</param>
          <param name="ki">0.0</param>
      </command_interface>
      <state_interface name="position">
        <param name="initial_value">0.0</param>
      </state_interface>
      <state_interface name="velocity">
        <param name="initial_value">0.0</param>
        <param name="max">0.1</param>
        <param name="min">-0.1</param>
      </state_interface>
      <state_interface name="effort">
        <param name="initial_value">0.0</param>
      </state_interface>
      <param name="can_id">10</param>
      <param name="max_torque">15.0</param>
      <param name="position_kp">10.0</param>
      <param name="q_ki">0.5</param>
      <param name="position_kd">0.0</param>
      <param name="q_windup">1.0</param>
      <param name="dq_kp">2.0</param>
      <param name="dq_ki">0.5</param>
      <param name="dq_kd">0.0</param>
      <param name="dq_windup">0.1</param>
      <param name="ddq_kp">25</param>
      <param name="ddq_kd">5.0</param>
    </joint>
    <joint name="front_left_second_joint">
      <command_interface name="effort">
        <!-- <param name="front_left_second_joint_kp">0.00001</param> -->
          <param name="kp">0.001</param>
          <param name="kd">1</param>
          <param name="ki">0.1</param>
        </command_interface>
      <state_interface name="position">
        <param name="initial_value">0.0</param>
      </state_interface>
      <state_interface name="velocity">
        <param name="initial_value">0.0</param>
        <param name="max">0.1</param>
        <param name="min">-0.1</param>
      </state_interface>
      <state_interface name="effort">
        <param name="initial_value">0.0</param>
      </state_interface>
      <param name="can_id">11</param>
      <param name="max_torque">10.0</param>
      <param name="position_kp">10.0</param>
      <param name="q_ki">0.5</param>
      <param name="position_kd">0.0</param>
      <param name="q_windup">1.0</param>
      <param name="dq_kp">2.0</param>
      <param name="dq_ki">0.5</param>
      <param name="dq_kd">0.0</param>
      <param name="dq_windup">0.1</param>
      <param name="ddq_kp">7.5</param>
      <param name="ddq_kd">1.0</param>
    </joint>
    <joint name="front_left_third_joint">
      <command_interface name="effort">
          <param name="kp">10</param>
          <param name="kd">1</param>
          <param name="ki">0.1</param>
      </command_interface>
      <state_interface name="position">
        <param name="initial_value">2.82</param>
      </state_interface>
      <state_interface name="velocity">
        <param name="initial_value">0.0</param>
      </state_interface>
      <state_interface name="effort">
        <param name="initial_value">0.0</param>
      </state_interface>
      <param name="can_id">12</param>
      <param name="max_torque">10.0</param>
      <param name="position_kp">10.0</param>
      <param name="q_ki">0.5</param>
      <param name="position_kd">0.0</param>
      <param name="q_windup">1.0</param>
      <param name="dq_kp">2.0</param>
      <param name="dq_ki">0.5</param>
      <param name="dq_kd">0.0</param>
      <param name="dq_windup">0.1</param>
      <param name="ddq_kp">7.5</param>
      <param name="ddq_kd">1.0</param>
    </joint>

    <!-- <joint name="front_left_fourth_joint">
      <state_interface name="position">
      </state_interface>
      <state_interface name="velocity">
        <param name="initial_value">0.0</param>
      </state_interface>
      <state_interface name="effort">
      </state_interface>
    </joint>

    <joint name="front_left_fifth_joint">
      <state_interface name="position">
      </state_interface>
      <state_interface name="velocity">
        <param name="initial_value">0.0</param>
      </state_interface>
      <state_interface name="effort">
      </state_interface>
    </joint> -->

    <joint name="front_right_first_joint">
      <command_interface name="effort"/>
      <state_interface name="position">
        <param name="initial_value">0.0</param>
      </state_interface>
      <state_interface name="velocity">
        <param name="initial_value">0.0</param>
      </state_interface>
      <state_interface name="effort">
        <param name="initial_value">0.0</param>
      </state_interface>
      <param name="can_id">20</param>
      <param name="max_torque">15.0</param>
      <param name="position_kp">10.0</param>
      <param name="q_ki">0.5</param>
      <param name="position_kd">0.0</param>
      <param name="q_windup">1.0</param>
      <param name="dq_kp">2.0</param>
      <param name="dq_ki">0.5</param>
      <param name="dq_kd">0.0</param>
      <param name="dq_windup">0.1</param>
      <param name="ddq_kp">25</param>
      <param name="ddq_kd">5.0</param>
    </joint>
    <joint name="front_right_second_joint">
      <command_interface name="effort"/>
      <state_interface name="position">
        <param name="initial_value">0.0</param>
      </state_interface>
      <state_interface name="velocity">
        <param name="initial_value">0.0</param>
      </state_interface>
      <state_interface name="effort">
        <param name="initial_value">0.0</param>
      </state_interface>
      <param name="can_id">21</param>
      <param name="max_torque">10.0</param>
      <param name="position_kp">10.0</param>
      <param name="q_ki">0.5</param>
      <param name="position_kd">0.0</param>
      <param name="q_windup">1.0</param>
      <param name="dq_kp">2.0</param>
      <param name="dq_ki">0.5</param>
      <param name="dq_kd">0.0</param>
      <param name="dq_windup">0.1</param>
      <param name="ddq_kp">7.5</param>
      <param name="ddq_kd">1.0</param>
    </joint>
    <joint name="front_right_third_joint">
      <command_interface name="effort"/>
      <state_interface name="position">
        <param name="initial_value">2.82</param>
      </state_interface>
      <state_interface name="velocity">
        <param name="initial_value">0.0</param>
      </state_interface>
      <state_interface name="effort">
        <param name="initial_value">0.0</param>
      </state_interface>
      <param name="can_id">22</param>
      <param name="max_torque">10.0</param>
      <param name="position_kp">10.0</param>
      <param name="q_ki">0.5</param>
      <param name="position_kd">0.0</param>
      <param name="q_windup">1.0</param>
      <param name="dq_kp">2.0</param>
      <param name="dq_ki">0.5</param>
      <param name="dq_kd">0.0</param>
      <param name="dq_windup">0.1</param>
      <param name="ddq_kp">7.5</param>
      <param name="ddq_kd">1.0</param>
    </joint>
    <joint name="rear_right_first_joint">
      <command_interface name="effort"/>
      <state_interface name="position">
        <param name="initial_value">0.0</param>
      </state_interface>
      <state_interface name="velocity">
        <param name="initial_value">0.0</param>
      </state_interface>
      <state_interface name="effort">
        <param name="initial_value">0.0</param>
      </state_interface>
      <param name="can_id">30</param>
      <param name="max_torque">15.0</param>
      <param name="position_kp">10.0</param>
      <param name="q_ki">0.5</param>
      <param name="position_kd">0.0</param>
      <param name="q_windup">1.0</param>
      <param name="dq_kp">2.0</param>
      <param name="dq_ki">0.5</param>
      <param name="dq_kd">0.0</param>
      <param name="dq_windup">0.1</param>
      <param name="ddq_kp">25</param>
      <param name="ddq_kd">5.0</param>
    </joint>
    <joint name="rear_right_second_joint">
      <command_interface name="effort"/>
      <state_interface name="position">
        <param name="initial_value">0.0</param>
      </state_interface>
      <state_interface name="velocity">
        <param name="initial_value">0.0</param>
      </state_interface>
      <state_interface name="effort">
        <param name="initial_value">0.0</param>
      </state_interface>
      <param name="can_id">31</param>
      <param name="max_torque">10.0</param>
      <param name="position_kp">10.0</param>
      <param name="q_ki">0.5</param>
      <param name="position_kd">0.0</param>
      <param name="q_windup">1.0</param>
      <param name="dq_kp">2.0</param>
      <param name="dq_ki">0.5</param>
      <param name="dq_kd">0.0</param>
      <param name="dq_windup">0.1</param>
      <param name="ddq_kp">7.5</param>
      <param name="ddq_kd">1.0</param>
    </joint>
    <joint name="rear_right_third_joint">
      <command_interface name="effort"/>
      <state_interface name="position">
        <param name="initial_value">2.82</param>
      </state_interface>
      <state_interface name="velocity">
        <param name="initial_value">0.0</param>
      </state_interface>
      <state_interface name="effort">
        <param name="initial_value">0.0</param>
      </state_interface>
      <param name="can_id">32</param>
      <param name="max_torque">10.0</param>
      <param name="position_kp">10.0</param>
      <param name="q_ki">0.5</param>
      <param name="position_kd">0.0</param>
      <param name="q_windup">1.0</param>
      <param name="dq_kp">2.0</param>
      <param name="dq_ki">0.5</param>
      <param name="dq_kd">0.0</param>
      <param name="dq_windup">0.1</param>
      <param name="ddq_kp">7.5</param>
      <param name="ddq_kd">1.0</param>
    </joint>
    <joint name="rear_left_first_joint">
      <command_interface name="effort"/>
      <state_interface name="position">
        <param name="initial_value">0.0</param>
      </state_interface>
      <state_interface name="velocity">
        <param name="initial_value">0.0</param>
      </state_interface>
      <state_interface name="effort">
        <param name="initial_value">0.0</param>
      </state_interface>
      <param name="can_id">40</param>
      <param name="max_torque">15.0</param>
      <param name="position_kp">10.0</param>
      <param name="q_ki">0.5</param>
      <param name="position_kd">0.0</param>
      <param name="q_windup">1.0</param>
      <param name="dq_kp">2.0</param>
      <param name="dq_ki">0.5</param>
      <param name="dq_kd">0.0</param>
      <param name="dq_windup">0.1</param>
      <param name="ddq_kp">25</param>
      <param name="ddq_kd">5.0</param>
    </joint>
    <joint name="rear_left_second_joint">
      <command_interface name="effort"/>
      <state_interface name="position">
        <param name="initial_value">0.0</param>
      </state_interface>
      <state_interface name="velocity">
        <param name="initial_value">0.0</param>
      </state_interface>
      <state_interface name="effort">
        <param name="initial_value">0.0</param>
      </state_interface>
      <param name="can_id">41</param>
      <param name="max_torque">10.0</param>
      <param name="position_kp">10.0</param>
      <param name="q_ki">0.5</param>
      <param name="position_kd">0.0</param>
      <param name="q_windup">1.0</param>
      <param name="dq_kp">2.0</param>
      <param name="dq_ki">0.5</param>
      <param name="dq_kd">0.0</param>
      <param name="dq_windup">0.1</param>
      <param name="ddq_kp">7.5</param>
      <param name="ddq_kd">1.0</param>
    </joint>
    <joint name="rear_left_third_joint">
      <command_interface name="effort"/>
      <state_interface name="position">
        <param name="initial_value">2.82</param>
      </state_interface>
      <state_interface name="velocity">
        <param name="initial_value">0.0</param>
      </state_interface>
      <state_interface name="effort">
        <param name="initial_value">0.0</param>
      </state_interface>
      <param name="can_id">42</param>
      <param name="max_torque">10.0</param>
      <param name="position_kp">10.0</param>
      <param name="q_ki">0.5</param>
      <param name="position_kd">0.0</param>
      <param name="q_windup">1.0</param>
      <param name="dq_kp">2.0</param>
      <param name="dq_ki">0.5</param>
      <param name="dq_kd">0.0</param>
      <param name="dq_windup">0.1</param>
      <param name="ddq_kp">7.5</param>
      <param name="ddq_kd">1.0</param>
    </joint>
    <!-- <xacro:ros2_control_passive_point name="rear_left_fourth_joint" />
    <xacro:ros2_control_passive_point name="rear_left_fifth_joint" /> -->
  </ros2_control>
  <!-- <xacro:imu_ros2_control/> -->
</robot>
